<?xml version="1.0" ?>
<!-- =================================================================================== -->
<!-- |    This document was autogenerated by xacro from ur_description/urdf/ur10e.xacro | -->
<!-- |    EDITING THIS FILE BY HAND IS NOT RECOMMENDED                                 | -->
<!-- =================================================================================== -->
<robot name="ur10e_allegro">
  <!--
    Base UR robot series xacro macro.

    NOTE: this is NOT a URDF. It cannot directly be loaded by consumers
    expecting a flattened '.urdf' file. See the top-level '.xacro' for that
    (but note: that .xacro must still be processed by the xacro command).

    For use in '.launch' files: use one of the 'load_urX.launch' convenience
    launch files.

    This file models the base kinematic chain of a UR robot, which then gets
    parameterised by various configuration files to convert it into a UR3(e),
    UR5(e), UR10(e) or UR16e.

    NOTE: the default kinematic parameters (ie: link lengths, frame locations,
    offets, etc) do not correspond to any particular robot. They are defaults
    only. There WILL be non-zero offsets between the Forward Kinematics results
    in TF (ie: robot_state_publisher) and the values reported by the Teach
    Pendant.

    For accurate (and robot-specific) transforms, the 'kinematics_parameters_file'
    parameter MUST point to a .yaml file containing the appropriate values for
    the targetted robot.

    If using the UniversalRobots/Universal_Robots_ROS_Driver, follow the steps
    described in the readme of that repository to extract the kinematic
    calibration from the controller and generate the required .yaml file.

    Main author of the migration to yaml configs: Ludovic Delval.

    Contributors to previous versions (in no particular order):

     - Felix Messmer
     - Kelsey Hawkins
     - Wim Meeussen
     - Shaun Edwards
     - Nadia Hammoudeh Garcia
     - Dave Hershberger
     - G. vd. Hoorn
     - Philip Long
     - Dave Coleman
     - Miguel Prada
     - Mathias Luedtke
     - Marcel Schnirring
     - Felix von Drigalski
     - Felix Exner
     - Jimmy Da Silva
     - Ajit Krisshna N L
     - Muhammad Asif Rana
  -->
  <!--
    NOTE: the macro defined in this file is NOT part of the public API of this
          package. Users CANNOT rely on this file being available, or stored in
          this location. Nor can they rely on the existence of the macro.
  -->
  <transmission name="shoulder_pan_trans">
    <type>transmission_interface/SimpleTransmission</type>
    <joint name="shoulder_pan_joint">
      <hardwareInterface>hardware_interface/PositionJointInterface</hardwareInterface>
    </joint>
    <actuator name="shoulder_pan_motor">
      <mechanicalReduction>1</mechanicalReduction>
    </actuator>
  </transmission>
  <transmission name="shoulder_lift_trans">
    <type>transmission_interface/SimpleTransmission</type>
    <joint name="shoulder_lift_joint">
      <hardwareInterface>hardware_interface/PositionJointInterface</hardwareInterface>
    </joint>
    <actuator name="shoulder_lift_motor">
      <mechanicalReduction>1</mechanicalReduction>
    </actuator>
  </transmission>
  <transmission name="elbow_trans">
    <type>transmission_interface/SimpleTransmission</type>
    <joint name="elbow_joint">
      <hardwareInterface>hardware_interface/PositionJointInterface</hardwareInterface>
    </joint>
    <actuator name="elbow_motor">
      <mechanicalReduction>1</mechanicalReduction>
    </actuator>
  </transmission>
  <transmission name="wrist_1_trans">
    <type>transmission_interface/SimpleTransmission</type>
    <joint name="wrist_1_joint">
      <hardwareInterface>hardware_interface/PositionJointInterface</hardwareInterface>
    </joint>
    <actuator name="wrist_1_motor">
      <mechanicalReduction>1</mechanicalReduction>
    </actuator>
  </transmission>
  <transmission name="wrist_2_trans">
    <type>transmission_interface/SimpleTransmission</type>
    <joint name="wrist_2_joint">
      <hardwareInterface>hardware_interface/PositionJointInterface</hardwareInterface>
    </joint>
    <actuator name="wrist_2_motor">
      <mechanicalReduction>1</mechanicalReduction>
    </actuator>
  </transmission>
  <transmission name="wrist_3_trans">
    <type>transmission_interface/SimpleTransmission</type>
    <joint name="wrist_3_joint">
      <hardwareInterface>hardware_interface/PositionJointInterface</hardwareInterface>
    </joint>
    <actuator name="wrist_3_motor">
      <mechanicalReduction>1</mechanicalReduction>
    </actuator>
  </transmission>
  <!-- links: main serial chain -->
  <link name="base_link"/>
  <link name="base_link_inertia">
    <visual>
      <origin rpy="0 0 3.141592653589793" xyz="0 0 0"/>
      <geometry>
        <mesh filename="meshes/ur10e/visual/base.dae"/>
      </geometry>
      <material name="LightGrey">
        <color rgba="0.7 0.7 0.7 1.0"/>
      </material>
    </visual>
    <collision>
      <origin rpy="0 0 3.141592653589793" xyz="0 0 0"/>
      <geometry>
        <mesh filename="meshes/ur10e/collision/base.stl"/>
      </geometry>
    </collision>
    <inertial>
      <mass value="4.0"/>
      <origin rpy="0 0 0" xyz="0 0 0"/>
      <inertia ixx="0.0061063308908" ixy="0.0" ixz="0.0" iyy="0.0061063308908" iyz="0.0" izz="0.01125"/>
    </inertial>
  </link>
  <link name="shoulder_link">
    <visual>
      <origin rpy="0 0 3.141592653589793" xyz="0 0 0"/>
      <geometry>
        <mesh filename="meshes/ur10e/visual/shoulder.dae"/>
      </geometry>
      <material name="LightGrey">
        <color rgba="0.7 0.7 0.7 1.0"/>
      </material>
    </visual>
    <collision>
      <origin rpy="0 0 3.141592653589793" xyz="0 0 0"/>
      <geometry>
        <mesh filename="meshes/ur10e/collision/shoulder.stl"/>
      </geometry>
    </collision>
    <inertial>
      <mass value="7.778"/>
      <origin rpy="0 0 0" xyz="0 0 0"/>
      <inertia ixx="0.03147431257693659" ixy="0.0" ixz="0.0" iyy="0.03147431257693659" iyz="0.0" izz="0.021875624999999996"/>
    </inertial>
  </link>
  <link name="upper_arm_link">
    <visual>
      <origin rpy="1.5707963267948966 0 -1.5707963267948966" xyz="0 0 0.1762"/>
      <geometry>
        <mesh filename="meshes/ur10e/visual/upperarm.dae"/>
      </geometry>
      <material name="LightGrey">
        <color rgba="0.7 0.7 0.7 1.0"/>
      </material>
    </visual>
    <collision>
      <origin rpy="1.5707963267948966 0 -1.5707963267948966" xyz="0 0 0.1762"/>
      <geometry>
        <mesh filename="meshes/ur10e/collision/upperarm.stl"/>
      </geometry>
    </collision>
    <inertial>
      <mass value="12.93"/>
      <origin rpy="0 1.5707963267948966 0" xyz="-0.306 0.0 0.175"/>
      <inertia ixx="0.42175380379841093" ixy="0.0" ixz="0.0" iyy="0.42175380379841093" iyz="0.0" izz="0.03636562499999999"/>
    </inertial>
  </link>
  <link name="forearm_link">
    <visual>
      <origin rpy="1.5707963267948966 0 -1.5707963267948966" xyz="0 0 0.0393"/>
      <geometry>
        <mesh filename="meshes/ur10e/visual/forearm.dae"/>
      </geometry>
      <material name="LightGrey">
        <color rgba="0.7 0.7 0.7 1.0"/>
      </material>
    </visual>
    <collision>
      <origin rpy="1.5707963267948966 0 -1.5707963267948966" xyz="0 0 0.0393"/>
      <geometry>
        <mesh filename="meshes/ur10e/collision/forearm.stl"/>
      </geometry>
    </collision>
    <inertial>
      <mass value="3.87"/>
      <origin rpy="0 1.5707963267948966 0" xyz="-0.285775 0.0 0.0393"/>
      <inertia ixx="0.11079302548902206" ixy="0.0" ixz="0.0" iyy="0.11079302548902206" iyz="0.0" izz="0.010884375"/>
    </inertial>
  </link>
  <link name="wrist_1_link">
    <visual>
      <!-- TODO: Move this to a parameter -->
      <origin rpy="1.5707963267948966 0 0" xyz="0 0 -0.135"/>
      <geometry>
        <mesh filename="meshes/ur10e/visual/wrist1.dae"/>
      </geometry>
      <material name="LightGrey">
        <color rgba="0.7 0.7 0.7 1.0"/>
      </material>
    </visual>
    <collision>
      <origin rpy="1.5707963267948966 0 0" xyz="0 0 -0.135"/>
      <geometry>
        <mesh filename="meshes/ur10e/collision/wrist1.stl"/>
      </geometry>
    </collision>
    <inertial>
      <mass value="1.96"/>
      <origin rpy="0 0 0" xyz="0 0 0"/>
      <inertia ixx="0.005108247956699999" ixy="0.0" ixz="0.0" iyy="0.005108247956699999" iyz="0.0" izz="0.005512499999999999"/>
    </inertial>
  </link>
  <link name="wrist_2_link">
    <visual>
      <origin rpy="0 0 0" xyz="0 0 -0.12"/>
      <geometry>
        <mesh filename="meshes/ur10e/visual/wrist2.dae"/>
      </geometry>
      <material name="LightGrey">
        <color rgba="0.7 0.7 0.7 1.0"/>
      </material>
    </visual>
    <collision>
      <origin rpy="0 0 0" xyz="0 0 -0.12"/>
      <geometry>
        <mesh filename="meshes/ur10e/collision/wrist2.stl"/>
      </geometry>
    </collision>
    <inertial>
      <mass value="1.96"/>
      <origin rpy="0 0 0" xyz="0 0 0"/>
      <inertia ixx="0.005108247956699999" ixy="0.0" ixz="0.0" iyy="0.005108247956699999" iyz="0.0" izz="0.005512499999999999"/>
    </inertial>
  </link>
  <link name="wrist_3_link">
    <visual>
      <origin rpy="1.5707963267948966 0 0" xyz="0 0 -0.1168"/>
      <geometry>
        <mesh filename="meshes/ur10e/visual/wrist3.dae"/>
      </geometry>
      <material name="LightGrey">
        <color rgba="0.7 0.7 0.7 1.0"/>
      </material>
    </visual>
    <collision>
      <origin rpy="1.5707963267948966 0 0" xyz="0 0 -0.1168"/>
      <geometry>
        <mesh filename="meshes/ur10e/collision/wrist3.stl"/>
      </geometry>
    </collision>
    <inertial>
      <mass value="0.202"/>
      <origin rpy="0 0 0" xyz="0.0 0.0 -0.025"/>
      <inertia ixx="0.00014434577559500002" ixy="0.0" ixz="0.0" iyy="0.00014434577559500002" iyz="0.0" izz="0.00020452500000000002"/>
    </inertial>
  </link>
  <!-- joints: main serial chain -->
  <joint name="base_link-base_link_inertia" type="fixed">
    <parent link="base_link"/>
    <child link="base_link_inertia"/>
    <!-- 'base_link' is REP-103 aligned (so X+ forward), while the internal
           frames of the robot/controller have X+ pointing backwards.
           Use the joint between 'base_link' and 'base_link_inertia' (a dummy
           link/frame) to introduce the necessary rotation over Z (of pi rad).
      -->
    <origin rpy="0 0 3.141592653589793" xyz="0 0 0"/>
  </joint>
  <joint name="shoulder_pan_joint" type="revolute">
    <parent link="base_link_inertia"/>
    <child link="shoulder_link"/>
    <origin rpy="0 0 0" xyz="0 0 0.1807"/>
    <axis xyz="0 0 1"/>
    <limit effort="330.0" lower="-6.283185307179586" upper="6.283185307179586" velocity="2.0943951023931953"/>
    <dynamics damping="0" friction="0"/>
  </joint>
  <joint name="shoulder_lift_joint" type="revolute">
    <parent link="shoulder_link"/>
    <child link="upper_arm_link"/>
    <origin rpy="1.570796327 0 0" xyz="0 0 0"/>
    <axis xyz="0 0 1"/>
    <limit effort="330.0" lower="-6.283185307179586" upper="6.283185307179586" velocity="2.0943951023931953"/>
    <dynamics damping="0" friction="0"/>
  </joint>
  <joint name="elbow_joint" type="revolute">
    <parent link="upper_arm_link"/>
    <child link="forearm_link"/>
    <origin rpy="0 0 0" xyz="-0.6127 0 0"/>
    <axis xyz="0 0 1"/>
    <limit effort="150.0" lower="-3.141592653589793" upper="3.141592653589793" velocity="3.141592653589793"/>
    <dynamics damping="0" friction="0"/>
  </joint>
  <joint name="wrist_1_joint" type="revolute">
    <parent link="forearm_link"/>
    <child link="wrist_1_link"/>
    <origin rpy="0 0 0" xyz="-0.57155 0 0.17415"/>
    <axis xyz="0 0 1"/>
    <limit effort="56.0" lower="-6.283185307179586" upper="6.283185307179586" velocity="3.141592653589793"/>
    <dynamics damping="0" friction="0"/>
  </joint>
  <joint name="wrist_2_joint" type="revolute">
    <parent link="wrist_1_link"/>
    <child link="wrist_2_link"/>
    <origin rpy="1.570796327 0 0" xyz="0 -0.11985 -2.458164590756244e-11"/>
    <axis xyz="0 0 1"/>
    <limit effort="56.0" lower="-6.283185307179586" upper="6.283185307179586" velocity="3.141592653589793"/>
    <dynamics damping="0" friction="0"/>
  </joint>
  <joint name="wrist_3_joint" type="revolute">
    <parent link="wrist_2_link"/>
    <child link="wrist_3_link"/>
    <origin rpy="1.570796326589793 3.141592653589793 3.141592653589793" xyz="0 0.11655 -2.390480459346185e-11"/>
    <axis xyz="0 0 1"/>
    <limit effort="56.0" lower="-6.283185307179586" upper="6.283185307179586" velocity="3.141592653589793"/>
    <dynamics damping="0" friction="0"/>
  </joint>
  <!-- ROS-Industrial 'base' frame: base_link to UR 'Base' Coordinates transform -->
  <link name="base"/>
  <joint name="base_link-base_fixed_joint" type="fixed">
    <!-- Note the rotation over Z of pi radians: as base_link is REP-103
           aligned (ie: has X+ forward, Y+ left and Z+ up), this is needed
           to correctly align 'base' with the 'Base' coordinate system of
           the UR controller.
      -->
    <origin rpy="0 0 3.141592653589793" xyz="0 0 0"/>
    <parent link="base_link"/>
    <child link="base"/>
  </joint>
  <!-- ROS-Industrial 'flange' frame: attachment point for EEF models -->
  <link name="flange"/>
  <joint name="wrist_3-flange" type="fixed">
    <parent link="wrist_3_link"/>
    <child link="flange"/>
    <origin rpy="0 -1.5707963267948966 -1.5707963267948966" xyz="0 0 0"/>
  </joint>
  <!-- ROS-Industrial 'tool0' frame: all-zeros tool frame -->
  <link name="tool0"/>
  <joint name="flange-tool0" type="fixed">
    <!-- default toolframe: X+ left, Y+ up, Z+ front -->
    <origin rpy="1.5707963267948966 0 1.5707963267948966" xyz="0 0 0"/>
    <parent link="flange"/>
    <child link="tool0"/>
  </joint>
  
  <joint name="camera_mount_joint" type="fixed">
    <origin rpy="0 0 -3.14" xyz="0 0 0"/>
    <parent link="flange"/>
    <child link="camera_mount"/>
  </joint>
  <link name="camera_mount"/>

    <!-- ======================== BASE PARAMS ========================= -->
  <!-- ======================== FINGER PARAMS ======================== -->
  <!-- full height from joint to tip. when used,
       the radius of the finger tip sphere will be subtracted
       and one fixed link will be added for the tip. -->
  <!-- ========================= THUMB PARAMS ========================= -->
  <!-- ========================= LIMITS ========================= -->
  <!-- ============================================================================= -->
  <!-- BASE -->

  <link name="allegro_mount">
    <inertial>
      <mass value="0.05"/>
      <origin rpy="0 0 0" xyz="0 0 0"/>
      <inertia ixx="1e-4" ixy="0" ixz="0" iyy="1e-4" iyz="0" izz="1e-4"/>
    </inertial>
    <visual>
      <!-- <origin xyz="-0.0425 -0.0425 0" rpy="0 0 0" /> -->
      <origin rpy="0 0 0" xyz="0 0 0"/>
      <geometry>
        <mesh filename="meshes/mounts/allegro_mount.obj"/>
      </geometry>
      <material name="color_j7"/>
    </visual>
    <collision>
      <!-- <origin xyz="-0.0425 -0.0425 0" rpy="0 0 0" /> -->
      <origin rpy="0 0 0" xyz="0 0 0"/>
      <geometry>
        <mesh filename="meshes/mounts/allegro_mount.obj"/>
      </geometry>
    </collision>
  </link>
  <!-- <joint name="allegro_mount_joint1" type="fixed">
    
    <origin rpy="0 0 0" xyz="-0.00 -0.0 0.0"/>
    <parent link="iiwa7_link_ee"/>
    <child link="allegro_mount"/>

  </joint> -->
  <joint name="allegro_mount_joint" type="fixed">
    <!-- <origin xyz="0.065 0 0.0275" rpy="0 1.57 0" /> -->
    <origin rpy="0 -1.5708 0.785398" xyz="0.008219 -0.02063 0.08086"/>
    <parent link="allegro_mount"/>
    <child link="palm_link"/>

  </joint>
  
  <!-- BASE -->
  <link name="palm_link">
    <inertial>
      <mass value="0.4154"/>
      <origin rpy="0 0 0" xyz="0 0 0"/>
      <inertia ixx="1e-4" ixy="0" ixz="0" iyy="1e-4" iyz="0" izz="1e-4"/>
    </inertial>
    <visual>
      <geometry>
        <mesh filename="meshes/allegro/base_link.obj"/>
      </geometry>
      <origin rpy="0 0 0" xyz="0 0 0 "/>
      <material name="Grey">
        <color rgba="0.2 0.2 0.2 1"/>
      </material>
    </visual>
    <collision>
      <origin rpy="0.0 0 0" xyz="0 0 0"/>
      <geometry>
        <mesh filename="meshes/allegro/base_link.obj"/>
      </geometry>
    </collision>
  </link>
  <gazebo reference="palm_link">
    <material value="Gazebo/Grey"/>
  </gazebo>
  <!-- ============================================================================= -->
  <!-- FINGERS -->
  <!-- RIGHT HAND due to which finger is number 0 -->
  <!-- for LEFT HAND switch the sign of the **offset_origin_y** and **finger_angle_r** parameters-->
  <!-- [LINK 0, 4, 8] -->
  <link name="index_link_0">
    <collision>
      <geometry>
        <mesh filename="meshes/allegro/primary_base.obj"/>
      </geometry>
    </collision>
    <inertial>
      <mass value="0.005"/>
      <origin xyz="0 0 0"/>
      <inertia ixx="5.1458e-05" iyy="5.1458e-05" izz="6.125e-05" ixy="0" ixz="0" iyz="0"/>  
    </inertial>
    <visual>
      <geometry>
        <mesh filename="meshes/allegro/primary_base.obj"/>
      </geometry>
      <material name="Grey">
        <color rgba="0.2 0.2 0.2 1"/>
      </material>
    </visual>
  </link>
  <link name="index_link_1">
    <collision>
      <geometry>
        <mesh filename="meshes/allegro/primary_proximal.obj"/>
      </geometry>
    </collision>
    <inertial>
      <mass value="0.125164"/>
      <origin xyz="0.027 0 0"/>
      <inertia ixx="6.39979e-06" iyy="8.88687e-05" izz="9.13751e-05" ixy="-3.26531e-06" ixz="1.23963e-05" iyz="2.07384e-05"/> 
    </inertial>
    <visual>
      <geometry>
        <mesh filename="meshes/allegro/primary_proximal.obj"/>
      </geometry>
      <material name="Grey">
        <color rgba="0.2 0.2 0.2 1"/>
      </material>
    </visual>
  </link>
  <link name="index_link_2">
    <collision>
      <geometry>
        <mesh filename="meshes/allegro/primary_medial.obj"/>
      </geometry>
    </collision>
    <inertial>
      <mass value="0.131691"/>
      <origin xyz="0.039 0 0"/>
      <inertia ixx="7.04217e-05" iyy="3.95744e-05" izz="6.61125e-05" ixy="-9.64342e-05" ixz="5.8796e-05" iyz="-3.62996e-05"/> 
    </inertial>
    <visual>
      <geometry>
        <mesh filename="meshes/allegro/primary_medial.obj"/>
      </geometry>
      <material name="Grey">
        <color rgba="0.2 0.2 0.2 1"/>
      </material>
    </visual>
  </link>
  <link name="index_link_3">
    <collision>
      <geometry>
        <mesh filename="meshes/biotac/biotac_sensor.obj"/>
      </geometry>
    </collision>
    <inertial>
      <mass value="0.0211922"/>
      <origin xyz="0.029 0 0"/>
      <inertia ixx="2.93743e-05" iyy="7.21391e-05" izz="7.59731e-05" ixy="-3.51896e-05" ixz="-6.31225e-05" iyz="-9.25392e-07"/>
    </inertial>
    <visual>
      <geometry>
        <mesh filename="meshes/biotac/biotac_sensor.obj"/>
      </geometry>
      <material name="Green">
        <color rgba="0. 0.5 0. 1"/>
      </material>
    </visual>
  </link>
  <link name="middle_link_0">
    <collision>
      <geometry>
        <mesh filename="meshes/allegro/primary_base.obj"/>
      </geometry>
    </collision>
    <inertial>
      <mass value="0.005"/>
      <origin xyz="0 0 0"/>
      <inertia ixx="5.1458e-05" iyy="5.1458e-05" izz="6.125e-05" ixy="0" ixz="0" iyz="0"/>  
    </inertial>
    <visual>
      <geometry>
        <mesh filename="meshes/allegro/primary_base.obj"/>
      </geometry>
      <material name="Grey">
        <color rgba="0.2 0.2 0.2 1"/>
      </material>
    </visual>
  </link>
  <link name="middle_link_1">
    <collision>
      <geometry>
        <mesh filename="meshes/allegro/primary_proximal.obj"/>
      </geometry>
    </collision>
    <inertial>
      <mass value="0.125164"/>
      <origin xyz="0.027 0 0"/>
      <inertia ixx="6.39979e-06" iyy="8.88687e-05" izz="9.13751e-05" ixy="-3.26531e-06" ixz="1.23963e-05" iyz="2.07384e-05"/> 
    </inertial>
    <visual>
      <geometry>
        <mesh filename="meshes/allegro/primary_proximal.obj"/>
      </geometry>
      <material name="Grey">
        <color rgba="0.2 0.2 0.2 1"/>
      </material>
    </visual>
  </link>
  <link name="middle_link_2">
    <collision>
      <geometry>
        <mesh filename="meshes/allegro/primary_medial.obj"/>
      </geometry>
    </collision>
    <inertial>
      <mass value="0.131691"/>
      <origin xyz="0.039 0 0"/>
      <inertia ixx="7.04217e-05" iyy="3.95744e-05" izz="6.61125e-05" ixy="-9.64342e-05" ixz="5.8796e-05" iyz="-3.62996e-05"/> 
    </inertial>
    <visual>
      <geometry>
        <mesh filename="meshes/allegro/primary_medial.obj"/>
      </geometry>
      <material name="Grey">
        <color rgba="0.2 0.2 0.2 1"/>
      </material>
    </visual>
  </link>
  <link name="middle_link_3">
    <collision>
      <geometry>
        <mesh filename="meshes/biotac/biotac_sensor.obj"/>
      </geometry>
    </collision>
    <inertial>
      <mass value="0.0211922"/>
      <origin xyz="0.029 0 0"/>
      <inertia ixx="2.93743e-05" iyy="7.21391e-05" izz="7.59731e-05" ixy="-3.51896e-05" ixz="-6.31225e-05" iyz="-9.25392e-07"/>
    </inertial>
    <visual>
      <geometry>
        <mesh filename="meshes/biotac/biotac_sensor.obj"/>
      </geometry>
      <material name="Green">
        <color rgba="0 0.5 0 1"/>
      </material>
    </visual>
  </link>
  <link name="ring_link_0">
    <collision>
      <geometry>
        <mesh filename="meshes/allegro/primary_base.obj"/>
      </geometry>
    </collision>
    <inertial>
      <mass value="0.005"/>
      <origin xyz="0 0 0"/>
      <inertia ixx="5.1458e-05" iyy="5.1458e-05" izz="6.125e-05" ixy="0" ixz="0" iyz="0"/>  
    </inertial>
    <visual>
      <geometry>
        <mesh filename="meshes/allegro/primary_base.obj"/>
      </geometry>
      <material name="Grey">
        <color rgba="0.2 0.2 0.2 1"/>
      </material>
    </visual>
  </link>
  <link name="ring_link_1">
    <collision>
      <geometry>
        <mesh filename="meshes/allegro/primary_proximal.obj"/>
      </geometry>
    </collision>
    <inertial>
      <mass value="0.125164"/>
      <origin xyz="0.027 0 0"/>
      <inertia ixx="6.39979e-06" iyy="8.88687e-05" izz="9.13751e-05" ixy="-3.26531e-06" ixz="1.23963e-05" iyz="2.07384e-05"/> 
    </inertial>
    <visual>
      <geometry>
        <mesh filename="meshes/allegro/primary_proximal.obj"/>
      </geometry>
      <material name="Grey">
        <color rgba="0.2 0.2 0.2 1"/>
      </material>
    </visual>
  </link>
  <link name="ring_link_2">
    <collision>
      <geometry>
        <mesh filename="meshes/allegro/primary_medial.obj"/>
      </geometry>
    </collision>
    <inertial>
      <mass value="0.131691"/>
      <origin xyz="0.039 0 0"/>
      <inertia ixx="7.04217e-05" iyy="3.95744e-05" izz="6.61125e-05" ixy="-9.64342e-05" ixz="5.8796e-05" iyz="-3.62996e-05"/> 
    </inertial>
    <visual>
      <geometry>
        <mesh filename="meshes/allegro/primary_medial.obj"/>
      </geometry>
      <material name="Grey">
        <color rgba="0.2 0.2 0.2 1"/>
      </material>
    </visual>
  </link>
  <link name="ring_link_3">
    <collision>
      <geometry>
        <mesh filename="meshes/biotac/biotac_sensor.obj"/>
      </geometry>
    </collision>
    <inertial>
      <mass value="0.0211922"/>
      <origin xyz="0.029 0 0"/>
      <inertia ixx="2.93743e-05" iyy="7.21391e-05" izz="7.59731e-05" ixy="-3.51896e-05" ixz="-6.31225e-05" iyz="-9.25392e-07"/>
    </inertial>
    <visual>
      <geometry>
        <mesh filename="meshes/biotac/biotac_sensor.obj"/>
      </geometry>
      <material name="Green">
        <color rgba="0 0.5 0 1"/>
      </material>
    </visual>
  </link>
  <link name="thumb_link_0">
    <collision>
      <geometry>
        <mesh filename="meshes/allegro/thumb_base.obj"/>
      </geometry>
    </collision>
    <inertial>
      <mass value="0.1"/>
      <inertia ixx="5.1458e-5" ixy="0" ixz="0" iyy="5.1458e-5" iyz="0" izz="6.125e-5"/>
    </inertial>
    <visual>
      <geometry>
        <mesh filename="meshes/allegro/thumb_base.obj"/>
      </geometry>
      <material name="Grey">
        <color rgba="0.2 0.2 0.2 1"/>
      </material>
    </visual>
  </link>
  <link name="thumb_link_1">
    <collision>
      <geometry>
        <mesh filename="meshes/allegro/thumb_proximal.obj"/>
      </geometry>
    </collision>
    <inertial>
      <mass value="0.1"/>
      <inertia ixx="5.1458e-5" ixy="0" ixz="0" iyy="5.1458e-5" iyz="0" izz="6.125e-5"/>
    </inertial>
    <visual>
      <geometry>
        <mesh filename="meshes/allegro/thumb_proximal.obj"/>
      </geometry>
      <material name="Grey">
        <color rgba="0.2 0.2 0.2 1"/>
      </material>
    </visual>
  </link>
  <link name="thumb_link_2">
    <collision>
      <geometry>
        <mesh filename="meshes/allegro/thumb_medial.obj"/>
      </geometry>
    </collision>
    <inertial>
      <mass value="0.1"/>
      <inertia ixx="5.1458e-5" ixy="0" ixz="0" iyy="5.1458e-5" iyz="0" izz="6.125e-5"/>
    </inertial>
    <visual>
      <geometry>
        <mesh filename="meshes/allegro/thumb_medial.obj"/>
      </geometry>
      <material name="Grey">
        <color rgba="0.2 0.2 0.2 1"/>
      </material>
    </visual>
  </link>
  <link name="thumb_link_3">
    <collision>
      <geometry>
        <mesh filename="meshes/biotac/biotac_sensor_thumb.obj"/>
      </geometry>
    </collision>
    <inertial>
      <mass value="0.1"/>
      <inertia ixx="5.1458e-5" ixy="0" ixz="0" iyy="5.1458e-5" iyz="0" izz="6.125e-5"/>
    </inertial>
    <visual>
      <geometry>
        <mesh filename="meshes/biotac/biotac_sensor_thumb.obj"/>
      </geometry>
      <material name="Green">
        <color rgba="0 0.5 0 1"/>
      </material>
    </visual>
  </link>
  <joint name="index_joint_0" type="revolute">
    <axis xyz="0 0 1"/>
    <limit effort="0.35" lower="-0.558488888889" upper="0.558488888889" velocity="6.283"/>
    <origin rpy="3.1415 -1.57075 -0.0872638888889" xyz="0.0514302 -0.03632 -0.0113"/>
    <parent link="palm_link"/>
    <child link="index_link_0"/>
    <dynamics damping="0.0414019" friction="0.0523963"/>
  </joint>
  <joint name="index_joint_1" type="revolute">
    <axis xyz="0 0 1"/>
    <limit effort="0.35" lower="-0.279244444444" upper="1.727825" velocity="6.283"/>
    <origin rpy="3.1415 -1.57075 1.57075" xyz="0.0 0.0 0.0"/>
    <parent link="index_link_0"/>
    <child link="index_link_1"/>
    <dynamics damping="0.00587541" friction="0.0150275"/>
  </joint>
  <joint name="index_joint_2" type="revolute">
    <axis xyz="0 0 1"/>
    <limit effort="0.35" lower="-0.279244444444" upper="1.727825" velocity="6.283"/>
    <origin rpy="0.0 0.0 0.0" xyz="0.054 0.0 0.0"/>
    <parent link="index_link_1"/>
    <child link="index_link_2"/>
    <dynamics damping="0.010638" friction="0.00616359"/>
  </joint>
  <joint name="index_joint_3" type="revolute">
    <axis xyz="0 0 1"/>
    <limit effort="0.35" lower="-0.279244444444" upper="1.727825" velocity="6.283"/>
    <origin rpy="0.0 0.0 0.0" xyz="0.0384 0.0 0.0"/>
    <parent link="index_link_2"/>
    <child link="index_link_3"/>
    <dynamics damping="0.0226948" friction="0.0227036"/>
  </joint>
  <joint name="middle_joint_0" type="revolute">
    <axis xyz="0 0 1"/>
    <limit effort="0.35" lower="-0.558488888889" upper="0.558488888889" velocity="6.283"/>
    <origin rpy="3.1415 -1.57075 0" xyz="0.0537375 0.0087771 -0.0113"/>
    <parent link="palm_link"/>
    <child link="middle_link_0"/>
    <dynamics damping="0.0414019" friction="0.0523963"/>
  </joint>
  <joint name="middle_joint_1" type="revolute">
    <axis xyz="0 0 1"/>
    <limit effort="0.35" lower="-0.279244444444" upper="1.727825" velocity="6.283"/>
    <origin rpy="3.1415 -1.57075 1.57075" xyz="0.0 0.0 0.0"/>
    <parent link="middle_link_0"/>
    <child link="middle_link_1"/>
    <dynamics damping="0.00587541" friction="0.0150275"/>
  </joint>
  <joint name="middle_joint_2" type="revolute">
    <axis xyz="0 0 1"/>
    <limit effort="0.35" lower="-0.279244444444" upper="1.727825" velocity="6.283"/>
    <origin rpy="0.0 0.0 0.0" xyz="0.054 0.0 0.0"/>
    <parent link="middle_link_1"/>
    <child link="middle_link_2"/>
    <dynamics damping="0.010638" friction="0.00616359"/>
  </joint>
  <joint name="middle_joint_3" type="revolute">
    <axis xyz="0 0 1"/>
    <limit effort="0.35" lower="-0.279244444444" upper="1.727825" velocity="6.283"/>
    <origin rpy="0.0 0.0 0.0" xyz="0.0384 0.0 0.0"/>
    <parent link="middle_link_2"/>
    <child link="middle_link_3"/>
    <dynamics damping="0.0226948" friction="0.0227036"/>
  </joint>
  <joint name="ring_joint_0" type="revolute">
    <axis xyz="0 0 1"/>
    <limit effort="0.35" lower="-0.558488888889" upper="0.558488888889" velocity="6.283"/>
    <origin rpy="3.1415 -1.57075 0.0872638888889" xyz="0.0514302 0.0538749 -0.0113"/>
    <parent link="palm_link"/>
    <child link="ring_link_0"/>
    <dynamics damping="0.0414019" friction="0.0523963"/>
  </joint>
  <joint name="ring_joint_1" type="revolute">
    <axis xyz="0 0 1"/>
    <limit effort="0.35" lower="-0.279244444444" upper="1.727825" velocity="6.283"/>
    <origin rpy="3.1415 -1.57075 1.57075" xyz="0.0 0.0 0.0"/>
    <parent link="ring_link_0"/>
    <child link="ring_link_1"/>
    <dynamics damping="0.00587541" friction="0.0150275"/>
  </joint>
  <joint name="ring_joint_2" type="revolute">
    <axis xyz="0 0 1"/>
    <limit effort="0.35" lower="-0.279244444444" upper="1.727825" velocity="6.283"/>
    <origin rpy="0.0 0.0 0.0" xyz="0.054 0.0 0.0"/>
    <parent link="ring_link_1"/>
    <child link="ring_link_2"/>
    <dynamics damping="0.010638" friction="0.00616359"/>
  </joint>
  <joint name="ring_joint_3" type="revolute">
    <axis xyz="0 0 1"/>
    <limit effort="0.35" lower="-0.279244444444" upper="1.727825" velocity="6.283"/>
    <origin rpy="0.0 0.0 0.0" xyz="0.0384 0.0 0.0"/>
    <parent link="ring_link_2"/>
    <child link="ring_link_3"/>
    <dynamics damping="0.0226948" friction="0.0227036"/>
  </joint>
  <joint name="thumb_joint_0" type="revolute">
    <axis xyz="0 0 1"/>
    <limit effort="0.35" lower="0.279244444444" upper="1.57075" velocity="6.283"/>
    <origin rpy="-1.57075 -1.57075 1.48348611111" xyz="-0.0367482 -0.0081281 -0.0295"/>
    <parent link="palm_link"/>
    <child link="thumb_link_0"/>
    <dynamics friction="0.035"/>
  </joint>
  <joint name="thumb_joint_1" type="revolute">
    <axis xyz="0 0 1"/>
    <limit effort="0.35" lower="-0.331602777778" upper="1.15188333333" velocity="6.283"/>
    <origin rpy="1.57075 0 0" xyz="0.005 0.0 0.0"/>
    <parent link="thumb_link_0"/>
    <child link="thumb_link_1"/>
    <dynamics friction="0.035"/>
  </joint>
  <joint name="thumb_joint_2" type="revolute">
    <axis xyz="0 0 1"/>
    <limit effort="0.35" lower="-0.279244444444" upper="1.727825" velocity="6.283"/>
    <origin rpy="3.1415 -1.57075 0.0" xyz="0 0 0.0554"/>
    <parent link="thumb_link_1"/>
    <child link="thumb_link_2"/>
    <dynamics friction="0.035"/>
  </joint>
  <joint name="thumb_joint_3" type="revolute">
    <axis xyz="0 0 1"/>
    <limit effort="0.35" lower="-0.279244444444" upper="1.76273055556" velocity="6.283"/>
    <origin rpy="0.0 0.0 0.0" xyz="0.0514 0.0 0.0"/>
    <parent link="thumb_link_2"/>
    <child link="thumb_link_3"/>
    <dynamics friction="0.035"/>
  </joint>
  <!-- ============================================================================= -->

  <!-- Create a different *root* for the allegro hand -->
  <!-- Note: this offset is just eyeballed... -->
  <joint name="tool0_allegro" type="fixed">
    <parent link="tool0"/>
    <child link="allegro_mount"/>
    <origin rpy="0 0 0" xyz="0 0 0"/>
  </joint>
</robot>
